2025-04-26 11:09:09,080 - __main__ - INFO - Starting API access tests
2025-04-26 11:09:09,081 - __main__ - INFO - Mock mode set to 'never' from command line
2025-04-26 11:09:15,218 - __main__ - INFO - Service availability status:
2025-04-26 11:09:15,218 - __main__ - INFO -   API: Not available
2025-04-26 11:09:15,218 - __main__ - INFO -   Database: Available
2025-04-26 11:09:15,218 - __main__ - INFO -   Kafka: Not available
2025-04-26 11:09:15,218 - financial_app.tests.integration.data_layer_e2e.utils.reporting - INFO - Test reporting initialized. Report directory: D:\e backup\web development\plusEv\plusEV_code_base\plus_ev_code_base\live_trading_system\financial_app\tests\integration\data_layer_e2e\reports\20250426_110905
2025-04-26 11:09:19,324 - financial_app.tests.integration.data_layer_e2e.test_api_access - INFO - Running in forced real API mode (MOCK_MODE=never)
2025-04-26 11:09:19,324 - financial_app.tests.integration.data_layer_e2e.test_api_access - INFO - Starting API access tests...
2025-04-26 11:09:25,473 - financial_app.tests.integration.data_layer_e2e.test_api_access - INFO - Service availability: API=False, Database=True, Kafka=False
2025-04-26 11:09:25,473 - financial_app.tests.integration.data_layer_e2e.test_api_access - INFO - Test mode: REAL API
2025-04-26 11:09:25,473 - financial_app.tests.integration.data_layer_e2e.test_api_access - INFO - Authenticating with API...
2025-04-26 11:09:29,559 - financial_app.tests.integration.data_layer_e2e.test_api_access - ERROR - Failed to authenticate with API: HTTPConnectionPool(host='localhost', port=8000): Max retries exceeded with url: /api/auth/login (Caused by NewConnectionError('<urllib3.connection.HTTPConnection object at 0x00000213528F7E30>: Failed to establish a new connection: [WinError 10061] No connection could be made because the target machine actively refused it'))
2025-04-26 11:09:29,560 - financial_app.tests.integration.data_layer_e2e.utils.reporting - INFO - Test 'api_authentication' completed with status: FAIL
2025-04-26 11:09:29,560 - financial_app.tests.integration.data_layer_e2e.utils.reporting - ERROR - Test 'api_authentication' error: Authentication failed: HTTPConnectionPool(host='localhost', port=8000): Max retries exceeded with url: /api/auth/login (Caused by NewConnectionError('<urllib3.connection.HTTPConnection object at 0x00000213528F7E30>: Failed to establish a new connection: [WinError 10061] No connection could be made because the target machine actively refused it'))
2025-04-26 11:09:29,560 - financial_app.tests.integration.data_layer_e2e.test_api_access - ERROR - Authentication failed. Aborting API tests.
2025-04-26 11:09:29,569 - financial_app.tests.integration.data_layer_e2e.utils.reporting - INFO - Test report finalized with overall status: FAIL
2025-04-26 11:09:29,569 - financial_app.tests.integration.data_layer_e2e.utils.reporting - INFO - Report available at: D:\e backup\web development\plusEv\plusEV_code_base\plus_ev_code_base\live_trading_system\financial_app\tests\integration\data_layer_e2e\reports\20250426_110905
2025-04-26 11:09:29,570 - __main__ - INFO - Performance Metrics:
2025-04-26 11:09:29,571 - __main__ - INFO - api_authentication_ms: avg=4086.66ms, p95=4086.66ms
2025-04-26 11:09:29,571 - __main__ - INFO - API access tests completed with FAILURE
